Train Epoch: 1 [0/60000 (0%)]	Loss: 2.309521
Train Epoch: 1 [10240/60000 (17%)]	Loss: 2.295750
Train Epoch: 1 [20480/60000 (34%)]	Loss: 2.286760
Train Epoch: 1 [30720/60000 (51%)]	Loss: 2.275412
Train Epoch: 1 [40960/60000 (68%)]	Loss: 2.268139
Train Epoch: 1 [51200/60000 (85%)]	Loss: 2.255011
Validation set: Average loss: 2.2424, Accuracy: 3257/10000 (33%)
1 epoch elapsed time : 44.77046775817871
Train Epoch: 2 [0/60000 (0%)]	Loss: 2.245209
Train Epoch: 2 [10240/60000 (17%)]	Loss: 2.228048
Train Epoch: 2 [20480/60000 (34%)]	Loss: 2.210014
Train Epoch: 2 [30720/60000 (51%)]	Loss: 2.190144
Train Epoch: 2 [40960/60000 (68%)]	Loss: 2.182894
Train Epoch: 2 [51200/60000 (85%)]	Loss: 2.136843
Validation set: Average loss: 2.1064, Accuracy: 5531/10000 (55%)
2 epoch elapsed time : 81.74147295951843
model_checkpoints/model_2.pt Model Saved!!

Train Epoch: 3 [0/60000 (0%)]	Loss: 2.117744
Train Epoch: 3 [10240/60000 (17%)]	Loss: 2.093153
Train Epoch: 3 [20480/60000 (34%)]	Loss: 2.048772
Train Epoch: 3 [30720/60000 (51%)]	Loss: 1.988653
Train Epoch: 3 [40960/60000 (68%)]	Loss: 1.924612
Train Epoch: 3 [51200/60000 (85%)]	Loss: 1.853512
Error in sys.excepthook:
Traceback (most recent call last):
  File "A:\Users\SSY\anaconda3\envs\pytorch-dev-latest\lib\linecache.py", line 47, in getlines
    return updatecache(filename, module_globals)
  File "A:\Users\SSY\anaconda3\envs\pytorch-dev-latest\lib\linecache.py", line 137, in updatecache
    lines = fp.readlines()
  File "A:\Users\SSY\anaconda3\envs\pytorch-dev-latest\lib\codecs.py", line 319, in decode
    def decode(self, input, final=False):
KeyboardInterrupt

Original exception was:
Traceback (most recent call last):
  File "main.py", line 58, in <module>
    main()
  File "main.py", line 47, in main
    classifier.start_train(model_name=args.saved_model_name)
  File "A:\Users\SSY\Documents\GitHub\Pytorch-Base-Environment\Train.py", line 152, in start_train
    self.__validate(self.model, self.device, self.validation_loader)
  File "A:\Users\SSY\Documents\GitHub\Pytorch-Base-Environment\Train.py", line 101, in __validate
    for data, target in test_loader:
  File "A:\Users\SSY\anaconda3\envs\pytorch-dev-latest\lib\site-packages\torch\utils\data\dataloader.py", line 278, in __iter__
    return _MultiProcessingDataLoaderIter(self)
  File "A:\Users\SSY\anaconda3\envs\pytorch-dev-latest\lib\site-packages\torch\utils\data\dataloader.py", line 682, in __init__
    w.start()
  File "A:\Users\SSY\anaconda3\envs\pytorch-dev-latest\lib\multiprocessing\process.py", line 112, in start
    self._popen = self._Popen(self)
  File "A:\Users\SSY\anaconda3\envs\pytorch-dev-latest\lib\multiprocessing\context.py", line 223, in _Popen
    return _default_context.get_context().Process._Popen(process_obj)
  File "A:\Users\SSY\anaconda3\envs\pytorch-dev-latest\lib\multiprocessing\context.py", line 322, in _Popen
    return Popen(process_obj)
  File "A:\Users\SSY\anaconda3\envs\pytorch-dev-latest\lib\multiprocessing\popen_spawn_win32.py", line 89, in __init__
    reduction.dump(process_obj, to_child)
  File "A:\Users\SSY\anaconda3\envs\pytorch-dev-latest\lib\multiprocessing\reduction.py", line 60, in dump
    ForkingPickler(file, protocol).dump(obj)
BrokenPipeError: [Errno 32] Broken pipe
